#VRML_SIM R2023b utf8

EXTERNPROTO "https://raw.githubusercontent.com/cyberbotics/webots/R2023b/projects/objects/backgrounds/protos/TexturedBackground.proto"
EXTERNPROTO "https://raw.githubusercontent.com/cyberbotics/webots/R2023b/projects/objects/backgrounds/protos/TexturedBackgroundLight.proto"
EXTERNPROTO "https://raw.githubusercontent.com/cyberbotics/webots/R2023b/projects/objects/apartment_structure/protos/Wall.proto"
EXTERNPROTO "../protos/RectangleArena.proto"
EXTERNPROTO "https://raw.githubusercontent.com/cyberbotics/webots/R2023b/projects/appearances/protos/Roughcast.proto"

WorldInfo {
}
Viewpoint {
  orientation -0.4121026221159752 0.3959401439081892 0.8206112546675801 1.8063113028801734
  position 0.14105726467625773 -3.9368314187006144 3.174631431895319
}
TexturedBackground {
}
TexturedBackgroundLight {
}
Wall {
  translation 2.25564 -1.36191 1.39889e-14
  rotation 0 0 1 1.57
  name "wall(135)"
  size 0.25 0.01 0.1
}
Wall {
  translation -1.24788 -0.117551 -2.04281e-14
  rotation 0 0 1 1.57
  name "wall(19)"
  size 0.25 0.01 0.1
}
Wall {
  translation -0.991593 0.124505 -2.13162e-14
  rotation 0 0 1 1.57
  name "wall(17)"
  size 0.25 0.01 0.1
}
Wall {
  translation -1.2406 1.1214 -2.13162e-14
  rotation 0 0 1 1.57
  name "wall(24)"
  size 0.25 0.01 0.1
}
Wall {
  translation -0.738563 0.634467 -2.13162e-14
  rotation 0 0 1 1.57
  name "wall(153)"
  size 0.25 0.01 0.1
}
Solid {
  translation 0.132916 0.130724 0.003
  children [
    Shape {
      appearance PBRAppearance {
        baseColor 1 0 0
        roughness 1
        metalness 0
      }
      geometry Plane {
        size 0.25 0.25
      }
    }
  ]
}
Solid {
  translation 0.132916 0.130724 0.002
  children [
    Shape {
      appearance PBRAppearance {
        baseColor 1 0.333 0
        roughness 1
        metalness 0
      }
      geometry Plane {
        size 0.75 0.75
      }
    }
  ]
}
Solid {
  translation 0.132916 0.130724 0.001
  children [
    Shape {
      appearance PBRAppearance {
        baseColor 1 1 0.498
        roughness 1
        metalness 0
      }
      geometry Plane {
        size 1.25 1.25
      }
    }
  ]
}
Solid {
  translation 0 -3.13456 0
  children [
    Shape {
      appearance PBRAppearance {
        baseColor 0.529 0.529 0.529
        roughness 1
        metalness 0
      }
      geometry Plane {
        size 5 1.25
      }
    }
  ]
  name "solid(1)"
}
Solid {
  translation 0.132916 -2.875 0.001
  children [
    Shape {
      appearance PBRAppearance {
        baseColor 0.02 0.427 1
        roughness 1
        metalness 0
      }
      geometry Plane {
        size 0.25 0.25
      }
    }
  ]
  name "solid(1)"
}
Robot {
  translation 0.140977 -2.87117 0.0197884
  rotation -0.0001379896539227806 -0.0001366144087626257 0.9999999811476792 1.5707691774699974
  children [
    Camera {
      translation 0.06 0 0.01
      boundingObject Box {
        size 0.01 0.01 0.01
      }
    }
    DEF BODY Shape {
      appearance PBRAppearance {
        baseColor 0.917647 0.145098 0.145098
        roughness 1
        metalness 0
      }
      geometry Box {
        size 0.13 0.11 0.01
      }
    }
    DEF WHEEL1 HingeJoint {
      jointParameters HingeJointParameters {
        position 2648.274036904762
        axis 0 1 0
        anchor 0.05 0.06 0
      }
      device [
        RotationalMotor {
          name "wheel1"
        }
      ]
      endPoint Solid {
        translation 0.050027643835450164 0.060001376159952685 1.4868656737482417e-05
        rotation -0.03131936816878956 -0.7067582086805458 0.7067615804782923 3.2042109044404725
        children [
          DEF WHEEL Shape {
            appearance PBRAppearance {
              baseColor 0.305882 0.898039 0.25098
              roughness 1
              metalness 0
            }
            geometry Cylinder {
              height 0.01
              radius 0.02
              subdivision 24
            }
          }
        ]
        boundingObject USE WHEEL
        physics Physics {
        }
      }
    }
    DEF WHEEL2 HingeJoint {
      jointParameters HingeJointParameters {
        position 1614.6182550672409
        axis 0 1 0
        anchor 0.05 -0.06 0
      }
      device [
        RotationalMotor {
          name "wheel2"
        }
      ]
      endPoint Solid {
        translation 0.04997085599275956 -0.06000151447827137 -1.1672193829256737e-05
        rotation -0.9936047002555776 0.07984204247360331 -0.07984327074755189 4.705968931932695
        children [
          USE WHEEL
        ]
        name "solid(1)"
        boundingObject USE WHEEL
        physics Physics {
        }
      }
    }
    DEF WHEEL3 HingeJoint {
      jointParameters HingeJointParameters {
        position 2648.2740669167288
        axis 0 1 0
        anchor -0.05 0.06 0
      }
      device [
        RotationalMotor {
          name "wheel3"
        }
      ]
      endPoint Solid {
        translation -0.04997457160780796 0.06000151413020552 1.8411920743915526e-05
        rotation -0.03130875349388603 -0.7067584446137446 0.7067618148441664 3.20418969048665
        children [
          USE WHEEL
        ]
        name "solid(2)"
        boundingObject USE WHEEL
        physics Physics {
        }
      }
    }
    DEF WHEEL4 HingeJoint {
      jointParameters HingeJointParameters {
        position 1614.6182957167089
        axis 0 1 0
        anchor -0.05 -0.06 0
      }
      device [
        RotationalMotor {
          name "wheel4"
        }
      ]
      endPoint Solid {
        translation -0.050027330505369616 -0.06000137580027601 -1.5437212769937592e-05
        rotation -0.9936079247098997 0.07982197444498657 -0.07982320683479407 4.705972178679287
        children [
          USE WHEEL
        ]
        name "solid(3)"
        boundingObject USE WHEEL
        physics Physics {
        }
      }
    }
    DEF DS_center DistanceSensor {
      translation 0.062 -3.05885e-08 0
      rotation 0 0 1 1.01503e-06
      children [
        Shape {
          appearance PBRAppearance {
            baseColor 0.184314 0.596078 0.847059
            roughness 1
            metalness 0
          }
          geometry Box {
            size 0.01 0.01 0.01
          }
        }
      ]
      name "ds_center"
    }
    DEF DS_right DistanceSensor {
      translation 0.062 -0.06 0
      rotation 0 0 1 -0.523595307179586
      children [
        Shape {
          appearance PBRAppearance {
            baseColor 0.184314 0.596078 0.847059
            roughness 1
            metalness 0
          }
          geometry Box {
            size 0.01 0.01 0.01
          }
        }
      ]
      name "ds_right"
    }
    DEF DS_right_90 DistanceSensor {
      translation 0.062 -0.06 0
      rotation 0 0 1 -1.5707953071795862
      children [
        Shape {
          appearance PBRAppearance {
            baseColor 0.184314 0.596078 0.847059
            roughness 1
            metalness 0
          }
          geometry Box {
            size 0.01 0.01 0.01
          }
        }
      ]
      name "ds_right_90"
    }
    DEF DS_left DistanceSensor {
      translation 0.062 0.06 0
      rotation 0 0 1 0.5236
      children [
        Shape {
          appearance PBRAppearance {
            baseColor 0.184314 0.596078 0.847059
            roughness 1
            metalness 0
          }
          geometry Box {
            size 0.01 0.01 0.01
          }
        }
      ]
      name "ds_left"
    }
    DEF DS_left_90 DistanceSensor {
      translation 0.062 0.06 0
      rotation 0 0 1 1.5708
      children [
        Shape {
          appearance PBRAppearance {
            baseColor 0.184314 0.596078 0.847059
            roughness 1
            metalness 0
          }
          geometry Box {
            size 0.01 0.01 0.01
          }
        }
      ]
      name "ds_left_90"
    }
  ]
  boundingObject USE BODY
  physics Physics {
    density -1
    mass 1
  }
  controller "python"
}
Wall {
  translation -0.744131 0.130346 -1.77635e-14
  rotation 0 0 1 1.57
  name "wall(16)"
  size 0.25 0.01 0.1
}
Wall {
  translation 0 2.5 0
  rotation 0.7071067811865475 0 0.7071067811865475 0
  size 5 0.01 0.1
  appearance Roughcast {
  }
}
Wall {
  translation 1.39 -2.5 0
  rotation 0.7071067811865475 0 0.7071067811865475 0
  name "wall(196)"
  size 2.25 0.01 0.1
  appearance Roughcast {
  }
}
Wall {
  translation -1.26 -2.5 0
  rotation 0.7071067811865475 0 0.7071067811865475 0
  name "wall(197)"
  size 2.5 0.01 0.1
  appearance Roughcast {
  }
}
Wall {
  translation -2.5 0 0
  rotation 0 0 1 1.5708
  size 5 0.01 0.1
  appearance Roughcast {
  }
}
Wall {
  translation 2.5 0 0
  rotation 0 0 1 1.5708
  size 5 0.01 0.1
  appearance Roughcast {
  }
}
Wall {
  translation -1.86893 -0.245118 7.10543e-15
  rotation 0.7071067811865475 0 0.7071067811865475 0
  name "wall(63)"
  size 0.75 0.01 0.1
}
Wall {
  translation -1.61972 -1.49369 7.99361e-15
  rotation 0.7071067811865475 0 0.7071067811865475 0
  name "wall(71)"
  size 0.75 0.01 0.1
}
Wall {
  translation -0.373827 -1.24381 -8.88178e-16
  rotation 0.7071067811865475 0 0.7071067811865475 0
  name "wall(22)"
  size 0.75 0.01 0.1
}
Wall {
  translation -0.119471 -1.49422 -1.77636e-15
  rotation 0.7071067811865475 0 0.7071067811865475 0
  name "wall(87)"
  size 0.75 0.01 0.1
}
Wall {
  translation 0.0025257 -2.24539 3.10863e-15
  rotation 0.7071067811865475 0 0.7071067811865475 0
  name "wall(90)"
  size 1 0.01 0.1
}
Wall {
  translation -1.61043 2.25527 -8.88178e-15
  rotation 0.7071067811865475 0 0.7071067811865475 0
  name "wall(26)"
  size 1.25 0.01 0.1
}
Wall {
  translation -1.74572 2.00974 -3.4639e-14
  rotation 0.7071067811865475 0 0.7071067811865475 0
  name "wall(45)"
  size 0.5 0.01 0.1
}
Wall {
  translation -1.37288 1.50909 -4.79616e-14
  rotation 0.7071067811865475 0 0.7071067811865475 0
  name "wall(52)"
  size 0.75 0.01 0.1
}
Wall {
  translation -1.11872 1.00611 -2.57572e-14
  rotation 0.7071067811865475 0 0.7071067811865475 0
  name "wall(3)"
  size 0.75 0.01 0.1
}
Wall {
  translation -0.99741 0.878728 -2.08721e-14
  rotation 0 0 1 1.57
  name "wall(25)"
  size 0.25 0.01 0.1
}
Wall {
  translation -0.622589 1.25532 -4.97379e-14
  rotation 0.7071067811865475 0 0.7071067811865475 0
  name "wall(56)"
  size 0.75 0.01 0.1
}
Wall {
  translation 2.12667 1.75879 -4.97379e-14
  rotation 0.7071067811865475 0 0.7071067811865475 0
  name "wall(186)"
  size 0.75 0.01 0.1
}
Wall {
  translation -0.111611 1.00604 -4.97379e-14
  rotation 0.7071067811865475 0 0.7071067811865475 0
  name "wall(150)"
  size 0.75 0.01 0.1
}
Wall {
  translation 2.12934 1.25918 -4.97379e-14
  rotation 0.7071067811865475 0 0.7071067811865475 0
  name "wall(189)"
  size 0.75 0.01 0.1
}
Wall {
  translation -0.864836 0.508449 -8.21564e-14
  rotation 0.7071067811865475 0 0.7071067811865475 0
  name "wall(9)"
  size 0.75 0.01 0.1
}
Wall {
  translation -0.368189 0.755565 -8.21564e-14
  rotation 0.7071067811865475 0 0.7071067811865475 0
  name "wall(99)"
  size 0.75 0.01 0.1
}
Wall {
  translation -1.3727 -1.24137 -8.21564e-14
  rotation 0.7071067811865475 0 0.7071067811865475 0
  name "wall(36)"
  size 0.75 0.01 0.1
}
Wall {
  translation 0.254907 -0.745224 -8.21564e-14
  rotation 0.7071067811865475 0 0.7071067811865475 0
  name "wall(41)"
  size 1 0.01 0.1
}
Wall {
  translation 0.503323 -0.990319 -8.21564e-14
  rotation 0.7071067811865475 0 0.7071067811865475 0
  name "wall(42)"
  size 1 0.01 0.1
}
Wall {
  translation 1.00592 0.258321 -7.90478e-14
  rotation 0.7071067811865475 0 0.7071067811865475 0
  name "wall(142)"
  size 1 0.01 0.1
}
Wall {
  translation 1.25543 0.00798053 -7.90478e-14
  rotation 0.7071067811865475 0 0.7071067811865475 0
  name "wall(144)"
  size 1 0.01 0.1
}
Wall {
  translation -1.85868 1.25556 -7.4607e-14
  rotation 0.7071067811865475 0 0.7071067811865475 0
  name "wall(55)"
  size 0.75 0.01 0.1
}
Wall {
  translation -1.87013 1.75814 -3.33067e-14
  name "wall(50)"
  size 0.25 0.01 0.1
}
Wall {
  translation -2.12191 0.0101222 -3.33067e-14
  name "wall(60)"
  size 0.25 0.01 0.1
}
Wall {
  translation -0.86943 0.253434 -3.06422e-14
  name "wall(12)"
  size 0.25 0.01 0.1
}
Wall {
  translation -0.115289 1.7511 -3.06422e-14
  name "wall(152)"
  size 0.25 0.01 0.1
}
Wall {
  translation 0.633213 1.50634 -3.06422e-14
  name "wall(166)"
  size 0.25 0.01 0.1
}
Wall {
  translation 1.1343 0.749065 -3.06422e-14
  name "wall(174)"
  size 0.25 0.01 0.1
}
Wall {
  translation 0.379911 1.75404 -3.06422e-14
  name "wall(170)"
  size 0.25 0.01 0.1
}
Wall {
  translation 0.382851 1.25989 -3.06422e-14
  name "wall(168)"
  size 0.25 0.01 0.1
}
Wall {
  translation 0.630893 0.503118 -3.06422e-14
  name "wall(147)"
  size 0.25 0.01 0.1
}
Wall {
  translation 1.13234 1.2581 -7.10547e-15
  name "wall(177)"
  size 0.25 0.01 0.1
}
Wall {
  translation 1.38114 1.76056 -7.10547e-15
  name "wall(179)"
  size 0.25 0.01 0.1
}
Wall {
  translation 1.63449 1.50801 -7.10547e-15
  name "wall(187)"
  size 0.25 0.01 0.1
}
Wall {
  translation 1.63316 2.24896 -7.10547e-15
  name "wall(181)"
  size 0.25 0.01 0.1
}
Wall {
  translation 1.87783 2.0056 -7.10547e-15
  name "wall(182)"
  size 0.25 0.01 0.1
}
Wall {
  translation 2.133 2.24959 -7.10547e-15
  name "wall(184)"
  size 0.25 0.01 0.1
}
Wall {
  translation 2.1258 1.50142 -7.10547e-15
  name "wall(191)"
  size 0.25 0.01 0.1
}
Wall {
  translation 2.37976 2.00241 -7.10547e-15
  name "wall(185)"
  size 0.25 0.01 0.1
}
Wall {
  translation 0.130129 2.26062 -3.06422e-14
  name "wall(159)"
  size 0.25 0.01 0.1
}
Wall {
  translation -0.862704 -0.492881 -2.75336e-14
  name "wall(23)"
  size 0.25 0.01 0.1
}
Wall {
  translation -1.87156 -0.99381 -2.75336e-14
  name "wall(39)"
  size 0.25 0.01 0.1
}
Wall {
  translation -1.11567 -0.240401 -2.93099e-14
  name "wall(21)"
  size 0.25 0.01 0.1
}
Wall {
  translation -0.623121 0.00549634 8.88134e-16
  name "wall(13)"
  size 0.25 0.01 0.1
}
Wall {
  translation -0.623032 -0.243084 -4.44197e-20
  name "wall(14)"
  size 0.25 0.01 0.1
}
Wall {
  translation 0.384293 0.000205697 -4.44197e-20
  name "wall(98)"
  size 0.25 0.01 0.1
}
Wall {
  translation -0.367724 -0.493961 4.35207e-14
  name "wall(31)"
  size 0.25 0.01 0.1
}
Wall {
  translation -1.87219 -0.495945 -2.22045e-14
  name "wall(64)"
  size 0.25 0.01 0.1
}
Wall {
  translation -2.11654 -1.24412 -2.08722e-14
  name "wall(69)"
  size 0.25 0.01 0.1
}
Wall {
  translation -2.36968 -1.4911 -1.9984e-14
  name "wall(72)"
  size 0.25 0.01 0.1
}
Wall {
  translation -2.37144 -1.99496 -4.21885e-14
  name "wall(75)"
  size 0.25 0.01 0.1
}
Wall {
  translation -2.11899 -1.74243 -5.37348e-14
  name "wall(74)"
  size 0.25 0.01 0.1
}
Wall {
  translation -0.87032 -1.494 -5.55112e-14
  name "wall(86)"
  size 0.25 0.01 0.1
}
Wall {
  translation -0.119476 -1.7459 -5.68435e-14
  name "wall(89)"
  size 0.25 0.01 0.1
}
Wall {
  translation -2.3677 0.260896 -3.33067e-14
  name "wall(61)"
  size 0.25 0.01 0.1
}
Wall {
  translation -2.11657 1.50306 -5.99521e-14
  name "wall(53)"
  size 0.25 0.01 0.1
}
Wall {
  translation -1.24287 1.75881 -3.55272e-14
  rotation 0.7071067811865475 0 0.7071067811865475 0
  name "wall(48)"
  size 0.5 0.01 0.1
}
Wall {
  translation 1.0059 2.25613 -3.55272e-14
  rotation 0.7071067811865475 0 0.7071067811865475 0
  name "wall(162)"
  size 0.5 0.01 0.1
}
Wall {
  translation 0.757965 1.0065 -3.59713e-14
  rotation 0.7071067811865475 0 0.7071067811865475 0
  name "wall(171)"
  size 0.5 0.01 0.1
}
Wall {
  translation 2.00939 0.755743 -3.59713e-14
  rotation 0.7071067811865475 0 0.7071067811865475 0
  name "wall(194)"
  size 0.5 0.01 0.1
}
Wall {
  translation 1.75403 0.497601 -3.41949e-14
  rotation 0.7071067811865475 0 0.7071067811865475 0
  name "wall(195)"
  size 0.5 0.01 0.1
}
Wall {
  translation -1.49401 0.253048 -7.54952e-14
  rotation 0.7071067811865475 0 0.7071067811865475 0
  name "wall(8)"
  size 0.5 0.01 0.1
}
Wall {
  translation 0.0078537 0.507499 -7.54952e-14
  rotation 0.7071067811865475 0 0.7071067811865475 0
  name "wall(101)"
  size 0.5 0.01 0.1
}
Wall {
  translation 0.74897 -0.24154 -7.4607e-14
  rotation 0.7071067811865475 0 0.7071067811865475 0
  name "wall(103)"
  size 0.5 0.01 0.1
}
Wall {
  translation 1.5044 -0.99388 -7.4607e-14
  rotation 0.7071067811865475 0 0.7071067811865475 0
  name "wall(109)"
  size 0.5 0.01 0.1
}
Wall {
  translation 2.00713 -0.250741 -7.41629e-14
  rotation 0.7071067811865475 0 0.7071067811865475 0
  name "wall(136)"
  size 0.5 0.01 0.1
}
Wall {
  translation 2.00103 -0.490932 -7.28306e-14
  rotation 0.7071067811865475 0 0.7071067811865475 0
  name "wall(137)"
  size 0.5 0.01 0.1
}
Wall {
  translation -2.24474 1.00881 -3.55272e-14
  rotation 0.7071067811865475 0 0.7071067811865475 0
  name "wall(58)"
  size 0.5 0.01 0.1
}
Wall {
  translation -0.121744 2.00774 -2.4869e-14
  rotation 0.7071067811865475 0 0.7071067811865475 0
  name "wall(43)"
  size 1.75 0.01 0.1
}
Wall {
  translation -1.36835 -0.49094 0
  rotation 0.7071067811865475 0 0.7071067811865475 0
  name "wall(4)"
  size 0.25 0.01 0.1
}
Wall {
  translation 0.131247 -1.99201 3.01981e-14
  rotation 0.7071067811865475 0 0.7071067811865475 0
  name "wall(5)"
  size 0.25 0.01 0.1
}
Wall {
  translation 0.629302 -1.99521 2.9754e-14
  rotation 0.7071067811865475 0 0.7071067811865475 0
  name "wall(93)"
  size 0.25 0.01 0.1
}
Wall {
  translation 0.628397 -1.24237 6.03962e-14
  rotation 0.7071067811865475 0 0.7071067811865475 0
  name "wall(38)"
  size 0.25 0.01 0.1
}
Wall {
  translation 1.13181 -0.74003 6.03962e-14
  rotation 0.7071067811865475 0 0.7071067811865475 0
  name "wall(106)"
  size 0.25 0.01 0.1
}
Wall {
  translation 1.13032 -1.23938 5.77317e-14
  rotation 0.7071067811865475 0 0.7071067811865475 0
  name "wall(108)"
  size 0.25 0.01 0.1
}
Wall {
  translation 2.13119 -0.747027 8.28228e-14
  rotation 0.7071067811865475 0 0.7071067811865475 0
  name "wall(129)"
  size 0.25 0.01 0.1
}
Wall {
  translation 2.12981 -1.23753 1.00586e-13
  rotation 0.7071067811865475 0 0.7071067811865475 0
  name "wall(133)"
  size 0.25 0.01 0.1
}
Wall {
  translation 2.38301 0.510664 7.12765e-14
  rotation 0.7071067811865475 0 0.7071067811865475 0
  name "wall(131)"
  size 0.25 0.01 0.1
}
Wall {
  translation 2.14067 0.250747 7.26087e-14
  rotation 0.7071067811865475 0 0.7071067811865475 0
  name "wall(140)"
  size 0.25 0.01 0.1
}
Wall {
  translation 2.38199 -0.999517 7.66055e-14
  rotation 0.7071067811865475 0 0.7071067811865475 0
  name "wall(139)"
  size 0.25 0.01 0.1
}
Wall {
  translation 2.38084 -1.4937 5.83978e-14
  rotation 0.7071067811865475 0 0.7071067811865475 0
  name "wall(132)"
  size 0.25 0.01 0.1
}
Wall {
  translation 1.37497 -1.74398 5.77317e-14
  rotation 0.7071067811865475 0 0.7071067811865475 0
  name "wall(116)"
  size 0.25 0.01 0.1
}
Wall {
  translation 2.12749 -1.74035 1.73196e-14
  rotation 0.7071067811865475 0 0.7071067811865475 0
  name "wall(120)"
  size 0.25 0.01 0.1
}
Wall {
  translation 2.3801 -1.99051 5.55113e-14
  rotation 0.7071067811865475 0 0.7071067811865475 0
  name "wall(127)"
  size 0.25 0.01 0.1
}
Wall {
  translation 1.87906 -2.24184 5.68435e-14
  rotation 0.7071067811865475 0 0.7071067811865475 0
  name "wall(126)"
  size 0.25 0.01 0.1
}
Wall {
  translation 1.62706 -2.00017 5.72876e-14
  rotation 0.7071067811865475 0 0.7071067811865475 0
  name "wall(125)"
  size 0.25 0.01 0.1
}
Wall {
  translation 0.879247 -2.24082 5.59553e-14
  rotation 0.7071067811865475 0 0.7071067811865475 0
  name "wall(113)"
  size 0.25 0.01 0.1
}
Wall {
  translation 1.12947 -1.99125 5.59553e-14
  rotation 0.7071067811865475 0 0.7071067811865475 0
  name "wall(114)"
  size 0.25 0.01 0.1
}
Wall {
  translation -1.36742 -0.991896 0
  name "wall(30)"
  size 0.25 0.01 0.1
}
Wall {
  translation -1.36717 -1.99267 -1.33227e-15
  name "wall(80)"
  size 0.25 0.01 0.1
}
Wall {
  translation -0.995039 -0.741605 1.77636e-15
  name "wall(32)"
  size 0.5 0.01 0.1
}
Wall {
  translation -1.241 0.00227659 -2.66453e-15
  name "wall(11)"
  size 0.5 0.01 0.1
}
Wall {
  translation -1.9953 -0.742814 -2.66453e-15
  name "wall(34)"
  size 0.5 0.01 0.1
}
Wall {
  translation -1.74738 -2.24362 -2.66453e-15
  name "wall(78)"
  size 0.5 0.01 0.1
}
Wall {
  translation -1.24431 -1.74237 4.26326e-14
  name "wall(82)"
  size 0.5 0.01 0.1
}
Wall {
  translation -0.744756 -1.99614 7.77156e-14
  name "wall(84)"
  size 0.5 0.01 0.1
}
Wall {
  translation 0.754264 -1.49459 5.59552e-14
  name "wall(94)"
  size 0.5 0.01 0.1
}
Wall {
  translation 1.75606 -1.49174 5.72875e-14
  name "wall(122)"
  size 0.5 0.01 0.1
}
Wall {
  translation 0.260833 -2.37584 -7.99356e-15
  rotation 0 0 1 1.57
  name "wall(37)"
  size 0.25 0.01 0.1
}
Wall {
  translation 1.24936 -1.87159 -5.77311e-15
  rotation 0 0 1 1.57
  name "wall(115)"
  size 0.25 0.01 0.1
}
Wall {
  translation 2.26213 -0.872785 -8.65962e-15
  rotation 0 0 1 1.57
  name "wall(123)"
  size 0.25 0.01 0.1
}
Wall {
  translation 2.01009 -0.620146 2.15385e-14
  rotation 0 0 1 1.57
  name "wall(134)"
  size 0.25 0.01 0.1
}
Wall {
  translation 1.50919 -1.37163 -7.10538e-15
  rotation 0 0 1 1.57
  name "wall(130)"
  size 0.25 0.01 0.1
}
Wall {
  translation 1.25898 -2.37426 -5.77311e-15
  rotation 0 0 1 1.57
  name "wall(117)"
  size 0.25 0.01 0.1
}
Wall {
  translation 1.50433 -2.12323 -4.44084e-15
  rotation 0 0 1 1.57
  name "wall(118)"
  size 0.25 0.01 0.1
}
Wall {
  translation 2.25807 -2.36801 -4.92938e-14
  rotation 0 0 1 1.57
  name "wall(119)"
  size 0.25 0.01 0.1
}
Wall {
  translation 1.25898 -2.37426 -5.77311e-15
  rotation 0 0 1 1.57
  name "wall(128)"
  size 0.25 0.01 0.1
}
RectangleArena {
  translation 0.0218543 -0.00428427 -1.77636e-15
  name "rectangle arena(1)"
  floorSize 5 5
  floorAppearance PBRAppearance {
    baseColor 0.529 0.529 0.529
    roughness 1
    metalness 0
  }
  wallThickness 0
  wallHeight 1e-06
}
Wall {
  translation 2.25885 0.88091 -3.10863e-15
  rotation 0 0 1 1.57
  name "wall(193)"
  size 0.25 0.01 0.1
}
Wall {
  translation -1.99121 -0.373423 -2.66454e-15
  rotation 0 0 1 1.57
  name "wall(65)"
  size 0.25 0.01 0.1
}
Wall {
  translation -1.99814 -1.37082 -3.99681e-15
  rotation 0 0 1 1.57
  name "wall(70)"
  size 0.25 0.01 0.1
}
Wall {
  translation -2.24775 -1.61951 -4.4409e-15
  rotation 0 0 1 1.57
  name "wall(73)"
  size 0.25 0.01 0.1
}
Wall {
  translation -1.99867 -2.11793 -1.95399e-14
  rotation 0 0 1 1.57
  name "wall(77)"
  size 0.25 0.01 0.1
}
Wall {
  translation -2.25035 -2.11857 -3.55272e-15
  rotation 0 0 1 1.57
  name "wall(76)"
  size 0.25 0.01 0.1
}
Wall {
  translation -1.24754 -0.870904 -2.66454e-15
  rotation 0 0 1 1.57
  name "wall(67)"
  size 0.25 0.01 0.1
}
Wall {
  translation -0.992768 -1.12149 -2.66454e-15
  rotation 0 0 1 1.57
  name "wall(40)"
  size 0.25 0.01 0.1
}
Wall {
  translation 0.762102 -0.86682 -2.66454e-15
  rotation 0 0 1 1.57
  name "wall(91)"
  size 0.25 0.01 0.1
}
Wall {
  translation 0.501885 -0.614674 -2.66454e-15
  rotation 0 0 1 1.57
  name "wall(96)"
  size 0.25 0.01 0.1
}
Wall {
  translation -0.898452 -0.75097 1.77636e-15
  rotation 0 0 1 1.57
  name "res(1)"
  size 0.01 0.1 0.1
  appearance Roughcast {
    colorOverride 0 1 0
    textureTransform TextureTransform {
      scale 2.4 1
    }
  }
}
Wall {
  translation -0.245872 -0.373607 1.77636e-15
  rotation 0 0 1 1.57
  name "wall(18)"
  size 0.25 0.01 0.1
}
Wall {
  translation 0.881956 -0.242399 1.77636e-15
  rotation 0 0 1 1.57
  name "res"
  size 0.01 0.1 0.1
  appearance Roughcast {
    colorOverride 0 1 0
    textureTransform TextureTransform {
      scale 2.4 1
    }
  }
}
Wall {
  translation 1.74676 0.132925 1.77636e-15
  rotation 0 0 1 1.57
  name "wall(145)"
  size 0.25 0.01 0.1
}
Wall {
  translation 2.25445 0.133582 3.10863e-15
  rotation 0 0 1 1.57
  name "wall(141)"
  size 0.25 0.01 0.1
}
Wall {
  translation 0.763737 -0.369048 1.77636e-15
  rotation 0 0 1 1.57
  name "wall(105)"
  size 0.25 0.01 0.1
}
Wall {
  translation 1.00374 -0.36924 1.77636e-15
  rotation 0 0 1 1.57
  name "wall(104)"
  size 0.25 0.01 0.1
}
Wall {
  translation -0.994838 1.37977 -2.30926e-14
  rotation 0 0 1 1.57
  name "wall(29)"
  size 0.25 0.01 0.1
}
Wall {
  translation -0.498354 0.379764 -1.90958e-14
  rotation 0 0 1 1.57
  name "wall(10)"
  size 0.25 0.01 0.1
}
Wall {
  translation 0.507388 0.625693 -1.90958e-14
  rotation 0 0 1 1.57
  name "wall(146)"
  size 0.25 0.01 0.1
}
Wall {
  translation 0.758718 0.880776 -1.90958e-14
  rotation 0 0 1 1.57
  name "wall(172)"
  size 0.25 0.01 0.1
}
Wall {
  translation -0.495639 -0.119292 -1.95399e-14
  rotation 0 0 1 1.57
  name "wall(15)"
  size 0.25 0.01 0.1
}
Wall {
  translation -0.991708 -0.368408 -2.22044e-14
  rotation 0 0 1 1.57
  name "wall(20)"
  size 0.25 0.01 0.1
}
Wall {
  translation -0.743696 2.13314 -2.66454e-15
  rotation 0 0 1 1.57
  name "wall(44)"
  size 0.25 0.01 0.1
}
Wall {
  translation -0.498391 2.37741 -2.66454e-15
  rotation 0 0 1 1.57
  name "wall(156)"
  size 0.25 0.01 0.1
}
Wall {
  translation -0.245144 2.13256 -2.66454e-15
  rotation 0 0 1 1.57
  name "wall(157)"
  size 0.25 0.01 0.1
}
Wall {
  translation 0.505547 2.13058 -2.66454e-15
  rotation 0 0 1 1.57
  name "wall(160)"
  size 0.25 0.01 0.1
}
Wall {
  translation 0.00187092 2.3763 -3.10863e-15
  rotation 0 0 1 1.57
  name "wall(158)"
  size 0.25 0.01 0.1
}
Wall {
  translation 1.25357 0.628543 -3.10863e-15
  rotation 0 0 1 1.57
  name "wall(175)"
  size 0.25 0.01 0.1
}
Wall {
  translation 1.51178 1.12664 -3.10863e-15
  rotation 0 0 1 1.57
  name "wall(176)"
  size 0.25 0.01 0.1
}
Wall {
  translation 1.75675 0.876232 -3.10863e-15
  rotation 0 0 1 1.57
  name "wall(192)"
  size 0.25 0.01 0.1
}
Wall {
  translation 1.25773 1.37879 -3.10863e-15
  rotation 0 0 1 1.57
  name "wall(178)"
  size 0.25 0.01 0.1
}
Wall {
  translation 1.75324 1.62964 -3.10863e-15
  rotation 0 0 1 1.57
  name "wall(188)"
  size 0.25 0.01 0.1
}
Wall {
  translation 0.757096 2.38307 -2.22045e-15
  rotation 0 0 1 1.57
  name "wall(161)"
  size 0.25 0.01 0.1
}
Wall {
  translation 1.25544 2.13255 -2.22045e-15
  rotation 0 0 1 1.57
  name "wall(163)"
  size 0.25 0.01 0.1
}
Wall {
  translation 0.507981 1.12608 -2.22045e-15
  rotation 0 0 1 1.57
  name "wall(169)"
  size 0.25 0.01 0.1
}
Wall {
  translation -1.23422 2.00974 8.88178e-15
  rotation 0 0 1 1.57
  name "wall(49)"
  size 0.5 0.01 0.1
}
Wall {
  translation -1.23422 2.00974 8.88178e-15
  rotation 0 0 1 1.57
  name "wall(154)"
  size 0.5 0.01 0.1
}
Wall {
  translation -0.498239 1.7517 8.88178e-15
  rotation 0 0 1 1.57
  name "wall(155)"
  size 0.5 0.01 0.1
}
Wall {
  translation 1.00755 1.75358 8.88178e-15
  rotation 0 0 1 1.57
  name "wall(164)"
  size 0.5 0.01 0.1
}
Wall {
  translation 2.00551 1.25278 8.88178e-15
  rotation 0 0 1 1.57
  name "wall(190)"
  size 0.5 0.01 0.1
}
Wall {
  translation 2.00919 2.00544 8.88178e-15
  rotation 0 0 1 1.57
  name "wall(183)"
  size 0.5 0.01 0.1
}
Wall {
  translation 0.758457 1.51064 8.88178e-15
  rotation 0 0 1 1.57
  name "wall(165)"
  size 0.5 0.01 0.1
}
Wall {
  translation 1.00801 0.756764 8.88178e-15
  rotation 0 0 1 1.57
  name "wall(173)"
  size 0.5 0.01 0.1
}
Wall {
  translation -0.496395 -0.747894 9.32587e-15
  rotation 0 0 1 1.57
  name "wall(28)"
  size 0.5 0.01 0.1
}
Wall {
  translation -1.49687 1.87888 -3.99681e-15
  rotation 0 0 1 1.57
  name "wall(47)"
  size 0.25 0.01 0.1
}
Wall {
  translation -1.74618 1.63137 -3.68594e-14
  rotation 0 0 1 1.57
  name "wall(51)"
  size 0.25 0.01 0.1
}
Wall {
  translation -1.99875 1.37587 -3.28626e-14
  rotation 0 0 1 1.57
  name "wall(54)"
  size 0.25 0.01 0.1
}
Wall {
  translation -2.24833 1.75501 1.33226e-15
  rotation 0 0 1 1.57
  name "wall(46)"
  size 0.5 0.01 0.1
}
Wall {
  translation -2.25027 0.506183 1.33226e-15
  rotation 0 0 1 1.57
  name "wall(62)"
  size 0.5 0.01 0.1
}
Wall {
  translation -0.244633 0.489972 1.33226e-15
  rotation 0 0 1 1.57
  name "wall(100)"
  size 0.5 0.01 0.1
}
Wall {
  translation -0.246105 1.50237 1.33226e-15
  rotation 0 0 1 1.57
  name "wall(148)"
  size 0.5 0.01 0.1
}
Wall {
  translation 0.507239 0.00405804 1.33226e-15
  rotation 0 0 1 1.57
  name "wall(102)"
  size 0.5 0.01 0.1
}
Wall {
  translation -1.75087 -0.994847 1.33226e-15
  rotation 0 0 1 1.57
  name "wall(35)"
  size 0.5 0.01 0.1
}
Wall {
  translation 0.256202 -0.243089 1.33226e-15
  rotation 0 0 1 1.57
  name "wall(97)"
  size 0.5 0.01 0.1
}
Wall {
  translation 1.50004 0.503967 -3.28626e-14
  rotation 0 0 1 1.57
  name "wall(143)"
  size 0.5 0.01 0.1
}
Wall {
  translation 1.75914 -0.993246 -7.62955e-21
  rotation 0 0 1 1.57
  name "wall(111)"
  size 0.5 0.01 0.1
}
Wall {
  translation -1.48945 0.756503 9.76996e-15
  rotation 0 0 1 1.57
  name "wall(6)"
  size 0.5 0.01 0.1
}
Wall {
  translation -1.23833 0.503102 1.11022e-14
  rotation 0 0 1 1.57
  name "wall(7)"
  size 0.5 0.01 0.1
}
Wall {
  translation -1.74341 0.502426 1.28786e-14
  rotation 0 0 1 1.57
  name "wall(57)"
  size 1.5 0.01 0.1
}
Wall {
  translation -0.741484 -1.49664 2.66454e-15
  rotation 0 0 1 1.57
  name "wall(2)"
  size 0.5 0.01 0.1
}
Wall {
  translation -1.23671 -2.24454 -2.84217e-14
  rotation 0 0 1 1.57
  name "wall(81)"
  size 0.5 0.01 0.1
}
Wall {
  translation -0.245458 -1.99441 -2.84217e-14
  rotation 0 0 1 1.57
  name "wall(88)"
  size 0.5 0.01 0.1
}
Wall {
  translation 0.500988 -1.99771 -2.62013e-14
  rotation 0 0 1 1.57
  name "wall(92)"
  size 0.5 0.01 0.1
}
Wall {
  translation 0.757971 -1.49238 -2.62013e-14
  rotation 0 0 1 1.57
  name "wall(95)"
  size 0.5 0.01 0.1
}
Wall {
  translation 1.75312 -1.75311 -2.35367e-14
  rotation 0 0 1 1.57
  name "wall(121)"
  size 0.5 0.01 0.1
}
Wall {
  translation -0.74243 -2.2463 -2.75335e-14
  rotation 0 0 1 1.57
  name "wall(85)"
  size 0.5 0.01 0.1
}
Wall {
  translation -1.49315 -0.623388 2.39808e-14
  rotation 0 0 1 1.57
  name "wall(66)"
  size 0.75 0.01 0.1
}
Wall {
  translation -2.24424 -0.874466 2.53131e-14
  rotation 0 0 1 1.57
  name "wall(68)"
  size 0.75 0.01 0.1
}
Wall {
  translation -0.745226 1.37669 5.19585e-14
  rotation 0 0 1 1.57
  name "wall(1)"
  size 0.75 0.01 0.1
}
Wall {
  translation 0.258207 0.628247 5.19585e-14
  rotation 0 0 1 1.57
  name "wall(149)"
  size 0.75 0.01 0.1
}
Wall {
  translation 0.00708767 1.38064 5.19585e-14
  rotation 0 0 1 1.57
  name "wall(151)"
  size 0.75 0.01 0.1
}
Wall {
  translation 1.50854 1.88021 5.19585e-14
  rotation 0 0 1 1.57
  name "wall(180)"
  size 0.75 0.01 0.1
}
Wall {
  translation 0.253297 1.63261 5.19585e-14
  rotation 0 0 1 1.57
  name "wall(167)"
  size 0.75 0.01 0.1
}
Wall {
  translation -1.74603 -1.86486 2.17604e-14
  rotation 0 0 1 1.57
  name "wall(79)"
  size 0.75 0.01 0.1
}
Wall {
  translation -0.993997 -1.87259 8.65974e-14
  rotation 0 0 1 1.57
  name "wall(83)"
  size 0.75 0.01 0.1
}
Wall {
  translation 0.261549 -1.49261 -8.88178e-15
  rotation 0 0 1 1.57
  name "wall(27)"
  size 1 0.01 0.1
}
Wall {
  translation 2.00516 0.126685 6.70575e-14
  rotation 0 0 1 1.57
  name "wall(110)"
  size 0.75 0.01 0.1
}
Wall {
  translation 1.50865 -0.621139 6.30607e-14
  rotation 0 0 1 1.57
  name "wall(138)"
  size 0.75 0.01 0.1
}
Wall {
  translation 1.00506 -1.8686 6.21726e-14
  rotation 0 0 1 1.57
  name "wall(112)"
  size 0.75 0.01 0.1
}
Wall {
  translation 2.00411 -1.86998 8.3933e-14
  rotation 0 0 1 1.57
  name "wall(124)"
  size 0.75 0.01 0.1
}
Wall {
  translation -2.00015 0.505819 0
  rotation 0 0 1 1.57
  name "wall(59)"
  size 1 0.01 0.1
}
Wall {
  translation 0.00586592 -0.246104 0
  rotation 0 0 1 1.57
  name "wall(33)"
  size 1 0.01 0.1
}
Wall {
  translation 1.25293 -0.999158 0
  rotation 0 0 1 1.57
  name "wall(107)"
  size 1 0.01 0.1
}
